Workbook
Name CT_RACEINCOME: #REF!
Name LA_DEMO: 'County PopulationPovertyRacial '!$A$1138:$L$1202
Name MD_KIN: 'MD Data'!$A$118:$D$143
Name MI_RACEINCOME: #REF!
Name CA_DEMO: 'County PopulationPovertyRacial '!$A$198:$L$256
Name AZ_RACEINCOME: #REF!
Name MD_FOSTER: 'MD Data'!$A$89:$D$114
Name PA_DEMO: 'County PopulationPovertyRacial '!$A$2289:$L$2356
Name MO_RACEINCOME: #REF!
Name TN_RACEINCOME: #REF!
Name VA_DEMO: 'County PopulationPovertyRacial '!$A$2873:$L$3006
Name CA_RACEINCOME: #REF!
Name MS_RACEINCOME: #REF!
Name MD_INHOME: 'MD Data'!$A$61:$D$87
Name CT_DEMO: 'County PopulationPovertyRacial '!$A$322:$L$330
Name NM_DEMO: 'County PopulationPovertyRacial '!$A$1833:$L$1866
Name OK_DEMO: 'County PopulationPovertyRacial '!$A$2174:$L$2251
Name RI_RACEINCOME: #REF!
Name AR_DEMO: 'County PopulationPovertyRacial '!$A$122:$L$197
Name MD_INCARE: 'MD Data'!$A$2:$D$27
Name ID_DEMO: 'County PopulationPovertyRacial '!$A$570:$L$614
Name MT_DEMO: 'County PopulationPovertyRacial '!$A$1631:$L$1687
Name IA_RACEINCOME: #REF!
Name TX_DEMO: 'County PopulationPovertyRacial '!$A$2573:$L$2827
Name AL_DEMO: 'County PopulationPovertyRacial '!$A$7:$L$74
Name TN_DEMO: 'County PopulationPovertyRacial '!$A$2477:$L$2572
Name MN_RACEINCOME: #REF!
Name MI_DEMO: 'County PopulationPovertyRacial '!$A$1260:$L$1343
Name MD_DEMO: 'County PopulationPovertyRacial '!$A$1220:$L$1244
Name MT_RACEINCOME: #REF!
Name OK_RACEINCOME: #REF!
Name ND_DEMO: 'County PopulationPovertyRacial '!$A$2031:$L$2084
Name IA_DEMO: 'County PopulationPovertyRacial '!$A$811:$L$910
Name VT_RACEINCOME: #REF!
Name WA_DEMO: 'County PopulationPovertyRacial '!$A$3007:$L$3046
Name TX_RACEINCOME: #REF!
Name LA_RACEINCOME: #REF!
Name AK_RACEINCOME: #REF!
Name GA_DEMO: 'County PopulationPovertyRacial '!$A$404:$L$563
Name MS_DEMO: 'County PopulationPovertyRacial '!$A$1432:$L$1514
Name AK_DEMO: 'County PopulationPovertyRacial '!$A$75:$L$105
Name AL_RACEINCOME: #REF!
Name NH_RACEINCOME: #REF!
Name FL_RACEINCOME: #REF!
Name CO_DEMO: 'County PopulationPovertyRacial '!$A$257:$L$321
Name OH_DEMO: 'County PopulationPovertyRacial '!$A$2085:$L$2173
Name SC_RACEINCOME: #REF!
Name NE_RACEINCOME: #REF!
Name NJ_DEMO: 'County PopulationPovertyRacial '!$A$1811:$L$1832
Name ME_RACEINCOME: #REF!
Name VT_DEMO: 'County PopulationPovertyRacial '!$A$2858:$L$2872
Name IN_RACEINCOME: #REF!
Name WV_DEMO: 'County PopulationPovertyRacial '!$A$3047:$L$3102
Name PA_RACEINCOME: #REF!
Name NJ_RACEINCOME: #REF!
Name NV_RACEINCOME: #REF!
Name WY_RACEINCOME: #REF!
Name NM_RACEINCOME: #REF!
Name SD_RACEINCOME: #REF!
Name HI_RACEINCOME: #REF!

Sheet All Data Connect
A1: id | B1: is_national | C1: is_state | D1: is_county | E1: state_code | F1: county_code | G1: county_state_code | H1: county_name | I1: state_name_full | J1: state_name_abv | K1: county_state | L1: number of children in care | M1: average beds per family | N1: number of children in foster care | O1: number of children in kinship care | P1: number of children placed out-of-county | Q1: number of foster and kinship homes | R1: number of children waiting for adoption | S1: number of children with 80+ connections made | T1: biological family reunification rate | U1: number of family preservation cases | V1: number of adoptive families | W1: number of biological families | X1: number of wraparound supporters | Y1: number of churches | Z1: foster family retention rate
A2: 1 | B2: 1
A3: 2 | C3: 1 | E3: 1 | I3: Alabama | J3: AL | L3: {=Alabama!C71:Q71} -> 5844 | M3: NULL | N3: NULL | O3: NULL | P3: NULL | Q3: 1989 | R3: 399 | S3: NULL | T3: NULL | U3: 4558 | V3: NULL | W3: NULL | X3: NULL | Y3: 0 | Z3: NULL
A4: 3 | D4: 1 | E4: 1 | F4: 1 | G4: =CONCATENATE(TEXT($E4,"00"),TEXT($F4,"000")) -> 01001 | H4: Autauga | I4: Alabama | J4: AL | K4: =CONCATENATE(H4,", ",J4) -> Autauga, AL | L4: {=Alabama!C3:Q69} -> NULL | M4: NULL | N4: NULL | O4: NULL | P4: NULL | Q4: NULL | R4: NULL | S4: NULL | T4: NULL | U4: NULL | V4: NULL | W4: NULL | X4: NULL | Y4: NULL | Z4: NULL
A5: 4 | D5: 1 | E5: 1 | F5: 3 | G5: =CONCATENATE(TEXT($E5,"00"),TEXT($F5,"000")) -> 01003 | H5: Baldwin | I5: Alabama | J5: AL | K5: =CONCATENATE(H5,", ",J5) -> Baldwin, AL | M5: NULL | N5: NULL | O5: NULL | P5: NULL | Q5: NULL | R5: NULL | S5: NULL | T5: NULL | U5: NULL | V5: NULL | W5: NULL | X5: NULL | Y5: NULL | Z5: NULL
A6: 5 | D6: 1 | E6: 1 | F6: 5 | G6: =CONCATENATE(TEXT($E6,"00"),TEXT($F6,"000")) -> 01005 | H6: Barbour | I6: Alabama | J6: AL | K6: =CONCATENATE(H6,", ",J6) -> Barbour, AL | M6: NULL | N6: NULL | O6: NULL | P6: NULL | Q6: NULL | R6: NULL | S6: NULL | T6: NULL | U6: NULL | V6: NULL | W6: NULL | X6: NULL | Y6: NULL | Z6: NULL
A7: 6 | D7: 1 | E7: 1 | F7: 7 | G7: =CONCATENATE(TEXT($E7,"00"),TEXT($F7,"000")) -> 01007 | H7: Bibb | I7: Alabama | J7: AL | K7: =CONCATENATE(H7,", ",J7) -> Bibb, AL | M7: NULL | N7: NULL | O7: NULL | P7: NULL | Q7: NULL | R7: NULL | S7: NULL | T7: NULL | U7: NULL | V7: NULL | W7: NULL | X7: NULL | Y7: NULL | Z7: NULL
A8: 7 | D8: 1 | E8: 1 | F8: 9 | G8: =CONCATENATE(TEXT($E8,"00"),TEXT($F8,"000")) -> 01009 | H8: Blount | I8: Alabama | J8: AL | K8: =CONCATENATE(H8,", ",J8) -> Blount, AL | M8: NULL | N8: NULL | O8: NULL | P8: NULL | Q8: NULL | R8: NULL | S8: NULL | T8: NULL | U8: NULL | V8: NULL | W8: NULL | X8: NULL | Y8: NULL | Z8: NULL
A9: 8 | D9: 1 | E9: 1 | F9: 11 | G9: =CONCATENATE(TEXT($E9,"00"),TEXT($F9,"000")) -> 01011 | H9: Bullock | I9: Alabama | J9: AL | K9: =CONCATENATE(H9,", ",J9) -> Bullock, AL | M9: NULL | N9: NULL | O9: NULL | P9: NULL | Q9: NULL | R9: NULL | S9: NULL | T9: NULL | U9: NULL | V9: NULL | W9: NULL | X9: NULL | Y9: NULL | Z9: NULL
A10: 9 | D10: 1 | E10: 1 | F10: 13 | G10: =CONCATENATE(TEXT($E10,"00"),TEXT($F10,"000")) -> 01013 | H10: Butler | I10: Alabama | J10: AL | K10: =CONCATENATE(H10,", ",J10) -> Butler, AL | M10: NULL | N10: NULL | O10: NULL | P10: NULL | Q10: NULL | R10: NULL | S10: NULL | T10: NULL | U10: NULL | V10: NULL | W10: NULL | X10: NULL | Y10: NULL | Z10: NULL
A11: 10 | D11: 1 | E11: 1 | F11: 15 | G11: =CONCATENATE(TEXT($E11,"00"),TEXT($F11,"000")) -> 01015 | H11: Calhoun | I11: Alabama | J11: AL | K11: =CONCATENATE(H11,", ",J11) -> Calhoun, AL | M11: NULL | N11: NULL | O11: NULL | P11: NULL | Q11: NULL | R11: NULL | S11: NULL | T11: NULL | U11: NULL | V11: NULL | W11: NULL | X11: NULL | Y11: NULL | Z11: NULL
A12: 11 | D12: 1 | E12: 1 | F12: 17 | G12: =CONCATENATE(TEXT($E12,"00"),TEXT($F12,"000")) -> 01017 | H12: Chambers | I12: Alabama | J12: AL | K12: =CONCATENATE(H12,", ",J12) -> Chambers, AL | M12: NULL | N12: NULL | O12: NULL | P12: NULL | Q12: NULL | R12: NULL | S12: NULL | T12: NULL | U12: NULL | V12: NULL | W12: NULL | X12: NULL | Y12: NULL | Z12: NULL
A13: 12 | D13: 1 | E13: 1 | F13: 19 | G13: =CONCATENATE(TEXT($E13,"00"),TEXT($F13,"000")) -> 01019 | H13: Cherokee | I13: Alabama | J13: AL | K13: =CONCATENATE(H13,", ",J13) -> Cherokee, AL | M13: NULL | N13: NULL | O13: NULL | P13: NULL | Q13: NULL | R13: NULL | S13: NULL | T13: NULL | U13: NULL | V13: NULL | W13: NULL | X13: NULL | Y13: NULL | Z13: NULL
A14: 13 | D14: 1 | E14: 1 | F14: 21 | G14: =CONCATENATE(TEXT($E14,"00"),TEXT($F14,"000")) -> 01021 | H14: Chilton | I14: Alabama | J14: AL | K14: =CONCATENATE(H14,", ",J14) -> Chilton, AL | M14: NULL | N14: NULL | O14: NULL | P14: NULL | Q14: NULL | R14: NULL | S14: NULL | T14: NULL | U14: NULL | V14: NULL | W14: NULL | X14: NULL | Y14: NULL | Z14: NULL
A15: 14 | D15: 1 | E15: 1 | F15: 23 | G15: =CONCATENATE(TEXT($E15,"00"),TEXT($F15,"000")) -> 01023 | H15: Choctaw | I15: Alabama | J15: AL | K15: =CONCATENATE(H15,", ",J15) -> Choctaw, AL | M15: NULL | N15: NULL | O15: NULL | P15: NULL | Q15: NULL | R15: NULL | S15: NULL | T15: NULL | U15: NULL | V15: NULL | W15: NULL | X15: NULL | Y15: NULL | Z15: NULL
A16: 15 | D16: 1 | E16: 1 | F16: 25 | G16: =CONCATENATE(TEXT($E16,"00"),TEXT($F16,"000")) -> 01025 | H16: Clarke | I16: Alabama | J16: AL | K16: =CONCATENATE(H16,", ",J16) -> Clarke, AL | M16: NULL | N16: NULL | O16: NULL | P16: NULL | Q16: NULL | R16: NULL | S16: NULL | T16: NULL | U16: NULL | V16: NULL | W16: NULL | X16: NULL | Y16: NULL | Z16: NULL
... A70: 69 | D70: 1 | E70: 1 | F70: 133 | G70: =CONCATENATE(TEXT($E70,"00"),TEXT($F70,"000")) -> 01133 | H70: Winston | I70: Alabama | J70: AL | K70: =CONCATENATE(H70,", ",J70) -> Winston, AL | M70: NULL | N70: NULL | O70: NULL | P70: NULL | Q70: NULL | R70: NULL | S70: NULL | T70: NULL | U70: NULL | V70: NULL | W70: NULL | X70: NULL | Y70: NULL | Z70: NULL
A71: 70 | C71: 1 | E71: 2 | G71: =CONCATENATE(TEXT($E71,"00"),TEXT($F71,"000")) -> 02000 | I71: Alaska | J71: AK | L71: {=Alaska!C9:Q9} -> 2261 | M71: 2.08 | N71: 1112 | O71: 1117 | P71: NULL | Q71: 1486 | R71: 853 | S71: NULL | T71: 0.4878 | U71: NULL | V71: NULL | W71: NULL | X71: NULL | Y71: 210 | Z71: NULL
A72: 71 | D72: 1 | E72: 2 | F72: 13 | G72: =CONCATENATE(TEXT($E72,"00"),TEXT($F72,"000")) -> 02013 | H72: Aleutians East | I72: Alaska | J72: AK | K72: =CONCATENATE(H72,", ",J72) -> Aleutians East, AK | L72: {=Alaska!C3:Q7} -> 858 | M72: NULL | N72: 431 | O72: 418 | P72: NULL | Q72: NULL | R72: 280 | S72: NULL | T72: 0.524 | U72: NULL | V72: NULL | W72: 0.524 | X72: NULL | Y72: 210 | Z72: NULL
A73: 72 | D73: 1 | E73: 2 | F73: 16 | G73: =CONCATENATE(TEXT($E73,"00"),TEXT($F73,"000")) -> 02016 | H73: Aleutians West | I73: Alaska | J73: AK | K73: =CONCATENATE(H73,", ",J73) -> Aleutians West, AK | L73: 440 | M73: NULL | N73: 242 | O73: 193 | P73: NULL | Q73: NULL | R73: 174 | S73: NULL | T73: 0.534 | U73: NULL | V73: NULL | W73: 0.534 | X73: NULL | Y73: NULL | Z73: NULL
A74: 73 | D74: 1 | E74: 2 | F74: 20 | G74: =CONCATENATE(TEXT($E74,"00"),TEXT($F74,"000")) -> 02020 | H74: Anchorage | I74: Alaska | J74: AK | K74: =CONCATENATE(H74,", ",J74) -> Anchorage, AK | L74: 562 | M74: NULL | N74: 261 | O74: 290 | P74: NULL | Q74: NULL | R74: 277 | S74: NULL | T74: NULL | U74: NULL | V74: NULL | W74: 0.498 | X74: NULL | Y74: NULL | Z74: NULL
A75: 74 | D75: 1 | E75: 2 | F75: 50 | G75: =CONCATENATE(TEXT($E75,"00"),TEXT($F75,"000")) -> 02050 | H75: Bethel | I75: Alaska | J75: AK | K75: =CONCATENATE(H75,", ",J75) -> Bethel, AK | L75: 146 | M75: NULL | N75: 76 | O75: 68 | P75: NULL | Q75: NULL | R75: 42 | S75: NULL | T75: NULL | U75: NULL | V75: NULL | W75: 0.397 | X75: NULL | Y75: NULL | Z75: NULL
A76: 75 | D76: 1 | E76: 2 | F76: 60 | G76: =CONCATENATE(TEXT($E76,"00"),TEXT($F76,"000")) -> 02060 | H76: Bristol Bay | I76: Alaska | J76: AK | K76: =CONCATENATE(H76,", ",J76) -> Bristol Bay, AK | L76: 255 | M76: NULL | N76: 102 | O76: 148 | P76: NULL | Q76: NULL | R76: 80 | S76: NULL | T76: NULL | U76: NULL | V76: NULL | W76: 0.486 | X76: NULL | Y76: NULL | Z76: NULL
A77: 76 | D77: 1 | E77: 2 | F77: 63 | G77: =CONCATENATE(TEXT($E77,"00"),TEXT($F77,"000")) -> 02063 | H77: Chugach | I77: Alaska | J77: AK | K77: =CONCATENATE(H77,", ",J77) -> Chugach, AK
A78: 77 | D78: 1 | E78: 2 | F78: 66 | G78: =CONCATENATE(TEXT($E78,"00"),TEXT($F78,"000")) -> 02066 | H78: Copper River | I78: Alaska | J78: AK | K78: =CONCATENATE(H78,", ",J78) -> Copper River, AK
A79: 78 | D79: 1 | E79: 2 | F79: 68 | G79: =CONCATENATE(TEXT($E79,"00"),TEXT($F79,"000")) -> 02068 | H79: Denali | I79: Alaska | J79: AK | K79: =CONCATENATE(H79,", ",J79) -> Denali, AK
A80: 79 | D80: 1 | E80: 2 | F80: 70 | G80: =CONCATENATE(TEXT($E80,"00"),TEXT($F80,"000")) -> 02070 | H80: Dillingham | I80: Alaska | J80: AK | K80: =CONCATENATE(H80,", ",J80) -> Dillingham, AK
A81: 80 | D81: 1 | E81: 2 | F81: 90 | G81: =CONCATENATE(TEXT($E81,"00"),TEXT($F81,"000")) -> 02090 | H81: Fairbanks North Star | I81: Alaska | J81: AK | K81: =CONCATENATE(H81,", ",J81) -> Fairbanks North Star, AK
A82: 81 | D82: 1 | E82: 2 | F82: 100 | G82: =CONCATENATE(TEXT($E82,"00"),TEXT($F82,"000")) -> 02100 | H82: Haines | I82: Alaska | J82: AK | K82: =CONCATENATE(H82,", ",J82) -> Haines, AK
A83: 82 | D83: 1 | E83: 2 | F83: 105 | G83: =CONCATENATE(TEXT($E83,"00"),TEXT($F83,"000")) -> 02105 | H83: Hoonah-Angoon | I83: Alaska | J83: AK | K83: =CONCATENATE(H83,", ",J83) -> Hoonah-Angoon, AK
A84: 83 | D84: 1 | E84: 2 | F84: 110 | G84: =CONCATENATE(TEXT($E84,"00"),TEXT($F84,"000")) -> 02110 | H84: Juneau | I84: Alaska | J84: AK | K84: =CONCATENATE(H84,", ",J84) -> Juneau, AK
A85: 84 | D85: 1 | E85: 2 | F85: 122 | G85: =CONCATENATE(TEXT($E85,"00"),TEXT($F85,"000")) -> 02122 | H85: Kenai Peninsula | I85: Alaska | J85: AK | K85: =CONCATENATE(H85,", ",J85) -> Kenai Peninsula, AK
A86: 85 | D86: 1 | E86: 2 | F86: 130 | G86: =CONCATENATE(TEXT($E86,"00"),TEXT($F86,"000")) -> 02130 | H86: Ketchikan Gateway | I86: Alaska | J86: AK | K86: =CONCATENATE(H86,", ",J86) -> Ketchikan Gateway, AK
A87: 86 | D87: 1 | E87: 2 | F87: 150 | G87: =CONCATENATE(TEXT($E87,"00"),TEXT($F87,"000")) -> 02150 | H87: Kodiak Island | I87: Alaska | J87: AK | K87: =CONCATENATE(H87,", ",J87) -> Kodiak Island, AK
A88: 87 | D88: 1 | E88: 2 | F88: 158 | G88: =CONCATENATE(TEXT($E88,"00"),TEXT($F88,"000")) -> 02158 | H88: Kusilvak | I88: Alaska | J88: AK | K88: =CONCATENATE(H88,", ",J88) -> Kusilvak, AK
... A101: 100 | D101: 1 | E101: 2 | F101: 290 | G101: =CONCATENATE(TEXT($E101,"00"),TEXT($F101,"000")) -> 02290 | H101: Yukon-Koyukuk | I101: Alaska | J101: AK | K101: =CONCATENATE(H101,", ",J101) -> Yukon-Koyukuk, AK
A102: 101 | C102: 1 | E102: 4 | G102: =CONCATENATE(TEXT($E102,"00"),TEXT($F102,"000")) -> 04000 | I102: Arizona | J102: AZ | L102: {=Arizona!C19:Q19} -> 8839 | M102: NULL | N102: NULL | O102: NULL | P102: NULL | Q102: 2170 | R102: 1606 | S102: NULL | T102: NULL | U102: NULL | V102: NULL | W102: NULL | X102: NULL | Y102: 2507 | Z102: NULL
A103: 102 | D103: 1 | E103: 4 | F103: 1 | G103: =CONCATENATE(TEXT($E103,"00"),TEXT($F103,"000")) -> 04001 | H103: Apache | I103: Arizona | J103: AZ | K103: =CONCATENATE(H103,", ",J103) -> Apache, AZ | L103: {=Arizona!C3:Q17} -> 26 | M103: NULL | N103: NULL | O103: NULL | P103: NULL | Q103: NULL | R103: NULL | S103: NULL | T103: NULL | U103: NULL | V103: NULL | W103: NULL | X103: NULL | Y103: 48 | Z103: NULL
A104: 103 | D104: 1 | E104: 4 | F104: 3 | G104: =CONCATENATE(TEXT($E104,"00"),TEXT($F104,"000")) -> 04003 | H104: Cochise | I104: Arizona | J104: AZ | K104: =CONCATENATE(H104,", ",J104) -> Cochise, AZ | L104: 215 | M104: NULL | N104: NULL | O104: NULL | P104: NULL | Q104: NULL | R104: NULL | S104: NULL | T104: NULL | U104: NULL | V104: NULL | W104: NULL | X104: NULL | Y104: 129 | Z104: NULL
A105: 104 | D105: 1 | E105: 4 | F105: 5 | G105: =CONCATENATE(TEXT($E105,"00"),TEXT($F105,"000")) -> 04005 | H105: Coconino | I105: Arizona | J105: AZ | K105: =CONCATENATE(H105,", ",J105) -> Coconino, AZ | L105: 120 | M105: NULL | N105: NULL | O105: NULL | P105: NULL | Q105: NULL | R105: NULL | S105: NULL | T105: NULL | U105: NULL | V105: NULL | W105: NULL | X105: NULL | Y105: 76 | Z105: NULL
...

Sheet Sheet75
A2: Alabama | B2: TOTAL | C2: =CONCATENATE("'",A2,"'!A:A") -> 'Alabama'!A:A | E2: =MATCH(B2,C2) -> 1
A3: Alaska | C3: =CONCATENATE("'",A3,"'!A:Q") -> 'Alaska'!A:Q | D3: =ROWS(C3) -> 1
A4: Arizona | C4: =CONCATENATE("'",A4,"'!A:Q") -> 'Arizona'!A:Q | D4: =ROWS(C4) -> 1
A5: Arkansas | C5: =CONCATENATE("'",A5,"'!A:Q") -> 'Arkansas'!A:Q | D5: =ROWS(C5) -> 1
A6: California | C6: =CONCATENATE("'",A6,"'!A:Q") -> 'California'!A:Q | D6: =ROWS(C6) -> 1
A7: Colorado | C7: =CONCATENATE("'",A7,"'!A:Q") -> 'Colorado'!A:Q | D7: =ROWS(C7) -> 1
A8: Connecticut | C8: =CONCATENATE("'",A8,"'!A:Q") -> 'Connecticut'!A:Q | D8: =ROWS(C8) -> 1
A9: District of Columbia | C9: =CONCATENATE("'",A9,"'!A:Q") -> 'District of Columbia'!A:Q | D9: =ROWS(C9) -> 1
A10: Delaware | C10: =CONCATENATE("'",A10,"'!A:Q") -> 'Delaware'!A:Q | D10: =ROWS(C10) -> 1
A11: Florida | C11: =CONCATENATE("'",A11,"'!A:Q") -> 'Florida'!A:Q | D11: =ROWS(C11) -> 1
A12: Georgia | C12: =CONCATENATE("'",A12,"'!A:Q") -> 'Georgia'!A:Q | D12: =ROWS(C12) -> 1
A13: Hawaii | C13: =CONCATENATE("'",A13,"'!A:Q") -> 'Hawaii'!A:Q | D13: =ROWS(C13) -> 1
A14: Idaho | C14: =CONCATENATE("'",A14,"'!A:Q") -> 'Idaho'!A:Q | D14: =ROWS(C14) -> 1
... A52: Wyoming | C52: =CONCATENATE("'",A52,"'!A:Q") -> 'Wyoming'!A:Q | D52: =ROWS(C52) -> 1

Sheet Metrics Check
A1: id | B1: is_national | C1: is_state | D1: is_county | E1: state_code | F1: county_code | G1: county_state_code | H1: county_name | I1: state_name_full | J1: state_name_abv | K1: county_state | L1: Number of Foster & Kinship Families Needed | M1: MTE Index
A2: 1 | B2: 1
A3: 2 | C3: 1 | E3: 1 | I3: Alabama | J3: AL
A4: 3 | D4: 1 | E4: 1 | F4: 1 | G4: =CONCATENATE(TEXT($E4,"00"),TEXT($F4,"000")) -> 01001 | H4: Autauga | I4: Alabama | J4: AL | K4: =CONCATENATE(H4,", ",J4) -> Autauga, AL
A5: 4 | D5: 1 | E5: 1 | F5: 3 | G5: =CONCATENATE(TEXT($E5,"00"),TEXT($F5,"000")) -> 01003 | H5: Baldwin | I5: Alabama | J5: AL | K5: =CONCATENATE(H5,", ",J5) -> Baldwin, AL
A6: 5 | D6: 1 | E6: 1 | F6: 5 | G6: =CONCATENATE(TEXT($E6,"00"),TEXT($F6,"000")) -> 01005 | H6: Barbour | I6: Alabama | J6: AL | K6: =CONCATENATE(H6,", ",J6) -> Barbour, AL
A7: 6 | D7: 1 | E7: 1 | F7: 7 | G7: =CONCATENATE(TEXT($E7,"00"),TEXT($F7,"000")) -> 01007 | H7: Bibb | I7: Alabama | J7: AL | K7: =CONCATENATE(H7,", ",J7) -> Bibb, AL
A8: 7 | D8: 1 | E8: 1 | F8: 9 | G8: =CONCATENATE(TEXT($E8,"00"),TEXT($F8,"000")) -> 01009 | H8: Blount | I8: Alabama | J8: AL | K8: =CONCATENATE(H8,", ",J8) -> Blount, AL
A9: 8 | D9: 1 | E9: 1 | F9: 11 | G9: =CONCATENATE(TEXT($E9,"00"),TEXT($F9,"000")) -> 01011 | H9: Bullock | I9: Alabama | J9: AL | K9: =CONCATENATE(H9,", ",J9) -> Bullock, AL
A10: 9 | D10: 1 | E10: 1 | F10: 13 | G10: =CONCATENATE(TEXT($E10,"00"),TEXT($F10,"000")) -> 01013 | H10: Butler | I10: Alabama | J10: AL | K10: =CONCATENATE(H10,", ",J10) -> Butler, AL
A11: 10 | D11: 1 | E11: 1 | F11: 15 | G11: =CONCATENATE(TEXT($E11,"00"),TEXT($F11,"000")) -> 01015 | H11: Calhoun | I11: Alabama | J11: AL | K11: =CONCATENATE(H11,", ",J11) -> Calhoun, AL
A12: 11 | D12: 1 | E12: 1 | F12: 17 | G12: =CONCATENATE(TEXT($E12,"00"),TEXT($F12,"000")) -> 01017 | H12: Chambers | I12: Alabama | J12: AL | K12: =CONCATENATE(H12,", ",J12) -> Chambers, AL
A13: 12 | D13: 1 | E13: 1 | F13: 19 | G13: =CONCATENATE(TEXT($E13,"00"),TEXT($F13,"000")) -> 01019 | H13: Cherokee | I13: Alabama | J13: AL | K13: =CONCATENATE(H13,", ",J13) -> Cherokee, AL
A14: 13 | D14: 1 | E14: 1 | F14: 21 | G14: =CONCATENATE(TEXT($E14,"00"),TEXT($F14,"000")) -> 01021 | H14: Chilton | I14: Alabama | J14: AL | K14: =CONCATENATE(H14,", ",J14) -> Chilton, AL
A15: 14 | D15: 1 | E15: 1 | F15: 23 | G15: =CONCATENATE(TEXT($E15,"00"),TEXT($F15,"000")) -> 01023 | H15: Choctaw | I15: Alabama | J15: AL | K15: =CONCATENATE(H15,", ",J15) -> Choctaw, AL
... A70: 69 | D70: 1 | E70: 1 | F70: 133 | G70: =CONCATENATE(TEXT($E70,"00"),TEXT($F70,"000")) -> 01133 | H70: Winston | I70: Alabama | J70: AL | K70: =CONCATENATE(H70,", ",J70) -> Winston, AL
A71: 70 | C71: 1 | E71: 2 | G71: =CONCATENATE(TEXT($E71,"00"),TEXT($F71,"000")) -> 02000 | I71: Alaska | J71: AK
A72: 71 | D72: 1 | E72: 2 | F72: 13 | G72: =CONCATENATE(TEXT($E72,"00"),TEXT($F72,"000")) -> 02013 | H72: Aleutians East | I72: Alaska | J72: AK | K72: =CONCATENATE(H72,", ",J72) -> Aleutians East, AK
A73: 72 | D73: 1 | E73: 2 | F73: 16 | G73: =CONCATENATE(TEXT($E73,"00"),TEXT($F73,"000")) -> 02016 | H73: Aleutians West | I73: Alaska | J73: AK | K73: =CONCATENATE(H73,", ",J73) -> Aleutians West, AK
A74: 73 | D74: 1 | E74: 2 | F74: 20 | G74: =CONCATENATE(TEXT($E74,"00"),TEXT($F74,"000")) -> 02020 | H74: Anchorage | I74: Alaska | J74: AK | K74: =CONCATENATE(H74,", ",J74) -> Anchorage, AK
A75: 74 | D75: 1 | E75: 2 | F75: 50 | G75: =CONCATENATE(TEXT($E75,"00"),TEXT($F75,"000")) -> 02050 | H75: Bethel | I75: Alaska | J75: AK | K75: =CONCATENATE(H75,", ",J75) -> Bethel, AK
A76: 75 | D76: 1 | E76: 2 | F76: 60 | G76: =CONCATENATE(TEXT($E76,"00"),TEXT($F76,"000")) -> 02060 | H76: Bristol Bay | I76: Alaska | J76: AK | K76: =CONCATENATE(H76,", ",J76) -> Bristol Bay, AK
A77: 76 | D77: 1 | E77: 2 | F77: 63 | G77: =CONCATENATE(TEXT($E77,"00"),TEXT($F77,"000")) -> 02063 | H77: Chugach | I77: Alaska | J77: AK | K77: =CONCATENATE(H77,", ",J77) -> Chugach, AK
A78: 77 | D78: 1 | E78: 2 | F78: 66 | G78: =CONCATENATE(TEXT($E78,"00"),TEXT($F78,"000")) -> 02066 | H78: Copper River | I78: Alaska | J78: AK | K78: =CONCATENATE(H78,", ",J78) -> Copper River, AK
A79: 78 | D79: 1 | E79: 2 | F79: 68 | G79: =CONCATENATE(TEXT($E79,"00"),TEXT($F79,"000")) -> 02068 | H79: Denali | I79: Alaska | J79: AK | K79: =CONCATENATE(H79,", ",J79) -> Denali, AK
A80: 79 | D80: 1 | E80: 2 | F80: 70 | G80: =CONCATENATE(TEXT($E80,"00"),TEXT($F80,"000")) -> 02070 | H80: Dillingham | I80: Alaska | J80: AK | K80: =CONCATENATE(H80,", ",J80) -> Dillingham, AK
A81: 80 | D81: 1 | E81: 2 | F81: 90 | G81: =CONCATENATE(TEXT($E81,"00"),TEXT($F81,"000")) -> 02090 | H81: Fairbanks North Star | I81: Alaska | J81: AK | K81: =CONCATENATE(H81,", ",J81) -> Fairbanks North Star, AK
A82: 81 | D82: 1 | E82: 2 | F82: 100 | G82: =CONCATENATE(TEXT($E82,"00"),TEXT($F82,"000")) -> 02100 | H82: Haines | I82: Alaska | J82: AK | K82: =CONCATENATE(H82,", ",J82) -> Haines, AK
A83: 82 | D83: 1 | E83: 2 | F83: 105 | G83: =CONCATENATE(TEXT($E83,"00"),TEXT($F83,"000")) -> 02105 | H83: Hoonah-Angoon | I83: Alaska | J83: AK | K83: =CONCATENATE(H83,", ",J83) -> Hoonah-Angoon, AK
... A101: 100 | D101: 1 | E101: 2 | F101: 290 | G101: =CONCATENATE(TEXT($E101,"00"),TEXT($F101,"000")) -> 02290 | H101: Yukon-Koyukuk | I101: Alaska | J101: AK | K101: =CONCATENATE(H101,", ",J101) -> Yukon-Koyukuk, AK
A102: 101 | C102: 1 | E102: 4 | G102: =CONCATENATE(TEXT($E102,"00"),TEXT($F102,"000")) -> 04000 | I102: Arizona | J102: AZ
A103: 102 | D103: 1 | E103: 4 | F103: 1 | G103: =CONCATENATE(TEXT($E103,"00"),TEXT($F103,"000")) -> 04001 | H103: Apache | I103: Arizona | J103: AZ | K103: =CONCATENATE(H103,", ",J103) -> Apache, AZ
A104: 103 | D104: 1 | E104: 4 | F104: 3 | G104: =CONCATENATE(TEXT($E104,"00"),TEXT($F104,"000")) -> 04003 | H104: Cochise | I104: Arizona | J104: AZ | K104: =CONCATENATE(H104,", ",J104) -> Cochise, AZ
A105: 104 | D105: 1 | E105: 4 | F105: 5 | G105: =CONCATENATE(TEXT($E105,"00"),TEXT($F105,"000")) -> 04005 | H105: Coconino | I105: Arizona | J105: AZ | K105: =CONCATENATE(H105,", ",J105) -> Coconino, AZ
A106: 105 | D106: 1 | E106: 4 | F106: 7 | G106: =CONCATENATE(TEXT($E106,"00"),TEXT($F106,"000")) -> 04007 | H106: Gila | I106: Arizona | J106: AZ | K106: =CONCATENATE(H106,", ",J106) -> Gila, AZ
A107: 106 | D107: 1 | E107: 4 | F107: 9 | G107: =CONCATENATE(TEXT($E107,"00"),TEXT($F107,"000")) -> 04009 | H107: Graham | I107: Arizona | J107: AZ | K107: =CONCATENATE(H107,", ",J107) -> Graham, AZ
A108: 107 | D108: 1 | E108: 4 | F108: 11 | G108: =CONCATENATE(TEXT($E108,"00"),TEXT($F108,"000")) -> 04011 | H108: Greenlee | I108: Arizona | J108: AZ | K108: =CONCATENATE(H108,", ",J108) -> Greenlee, AZ
A109: 108 | D109: 1 | E109: 4 | F109: 12 | G109: =CONCATENATE(TEXT($E109,"00"),TEXT($F109,"000")) -> 04012 | H109: La Paz | I109: Arizona | J109: AZ | K109: =CONCATENATE(H109,", ",J109) -> La Paz, AZ
A110: 109 | D110: 1 | E110: 4 | F110: 13 | G110: =CONCATENATE(TEXT($E110,"00"),TEXT($F110,"000")) -> 04013 | H110: Maricopa | I110: Arizona | J110: AZ | K110: =CONCATENATE(H110,", ",J110) -> Maricopa, AZ
A111: 110 | D111: 1 | E111: 4 | F111: 15 | G111: =CONCATENATE(TEXT($E111,"00"),TEXT($F111,"000")) -> 04015 | H111: Mohave | I111: Arizona | J111: AZ | K111: =CONCATENATE(H111,", ",J111) -> Mohave, AZ
...

Sheet State Overview
B1: State Overview
B2: State Demographics | L2: State-level Foster Care Data | P2: Church Data
C3: Population by Race
A4: State | B4: Population | C4: White | D4: Black or African American | E4: American Indian and Alaska Native | F4: Asian | G4: Native Hawaiian and Other Pacific Islander | H4: Other race | I4: Two or more races | J4: Median Household Income | K4: Child Poverty Rate (%) | L4: Number of Children in Out-of-Home Placement | M4: Number of Children Waiting for Adoption | N4: Number of Licensed Foster Homes | O4: Number of Family Preservation Cases | P4: Number of Churches | Q4: Number of Actively Engaged Churches Needed | R4: Number of Church Assessments Taken | S4: Churches per 1,000 People
A5: Alabama | B5: {=VLOOKUP($A5,AL_DEMO,{2,5,6,7,8,9,10,11,12,4},FALSE)} -> 5024279 | C5: 3220452 | D5: 1296162 | E5: 33625 | F5: 76660 | G5: 2984 | H5: 137443 | I5: 256953 | J5: 49881 | K5: 23.9 | L5: =Alabama!C71 -> 5844 | M5: =Alabama!H71 -> 1989 | N5: =Alabama!I71 -> 399 | O5: =Alabama!J71 -> NULL | P5: =Alabama!K71 -> NULL | Q5: =Alabama!L71 -> 4558 | R5: =Alabama!M71 -> NULL | S5: =(P5/B5)*1000 -> #VALUE!
A6: Alaska | B6: {=VLOOKUP($A6,AK_DEMO,{2,5,6,7,8,9,10,11,12,4},FALSE)} -> 733391 | C6: 435392 | D6: 21898 | E6: 111575 | F6: 44032 | G6: 12698 | H6: 18272 | I6: 89524 | J6: 74912 | K6: 14.5 | L6: =#REF! -> #REF! | M6: =VLOOKUP($A6,AFCARSCSC!$A$4:$D$56,3,FALSE) -> 328 | N6: =#REF! -> #REF! | O6: NULL | P6: =#REF! -> #REF! | Q6: =#REF! -> #REF! | R6: =#REF! -> #REF! | S6: =(P6/B6)*1000 -> #REF!
A7: Arizona | B7: {=VLOOKUP($A7,AZ_DEMO,{2,5,6,7,8,9,10,11,12,4},FALSE)} -> 7151502 | C7: 4322337 | D7: 339150 | E7: 319512 | F7: 257430 | G7: 16397 | H7: 899870 | I7: 996806 | J7: 59079 | K7: 20.4 | L7: =#REF! -> #REF! | M7: =#REF! -> #REF! | N7: =#REF! -> #REF! | O7: NULL | P7: =#REF! -> #REF! | Q7: =#REF! -> #REF! | R7: =#REF! -> #REF! | S7: =(P7/B7)*1000 -> #REF!
A8: Arkansas | B8: ='County PopulationPovertyRacial '!B122 -> 3011524 | C8: ='County PopulationPovertyRacial '!E122 -> 2114512 | D8: ='County PopulationPovertyRacial '!F122 -> 453783 | E8: ='County PopulationPovertyRacial '!G122 -> 27177 | F8: ='County PopulationPovertyRacial '!H122 -> 51839 | G8: ='County PopulationPovertyRacial '!I122 -> 14533 | H8: ='County PopulationPovertyRacial '!J122 -> 136105 | I8: ='County PopulationPovertyRacial '!K122 -> 213575 | J8: ='County PopulationPovertyRacial '!$L$122 -> 47094 | K8: ='County PopulationPovertyRacial '!D122 -> 23.8 | L8: =#REF! -> #REF! | M8: =#REF! -> #REF! | N8: =#REF! -> #REF! | O8: =#REF! -> #REF! | P8: =#REF! -> #REF! | Q8: =P8*0.1 -> #REF! | R8: =#REF! -> #REF! | S8: =(P8/B8)*1000 -> #REF!
A9: California | B9: {=VLOOKUP($A9,CA_DEMO,{2,5,6,7,8,9,10,11,12,4},FALSE)} -> 39538223 | C9: 16296122 | D9: 2237044 | E9: 631016 | F9: 6085947 | G9: 157263 | H9: 8370596 | I9: 5760235 | J9: 75250 | K9: 17.4 | L9: =#REF! -> #REF! | M9: {=VLOOKUP($A9,AFCARSCSC!$A$4:$D$56,{3,4},FALSE)} -> 8180 | N9: 34924 | O9: NULL | P9: =#REF! -> #REF! | Q9: =#REF! -> #REF! | R9: =#REF! -> #REF! | S9: =(P9/B9)*1000 -> #REF!
A10: Colorado | B10: {=VLOOKUP($A10,CO_DEMO,{2,5,6,7,8,9,10,11,12,4},FALSE)} -> 5773714 | C10: 4082927 | D10: 234828 | E10: 74129 | F10: 199827 | G10: 10287 | H10: 464046 | I10: 707670 | J10: 71949 | K10: 12.1 | L10: =#REF! -> #REF! | M10: {=VLOOKUP($A10,AFCARSCSC!$A$4:$D$56,{3,4},FALSE)} -> 560 | N10: 2078 | O10: NULL | P10: =#REF! -> #REF! | Q10: =#REF! -> #REF! | R10: =#REF! -> #REF! | S10: =(P10/B10)*1000 -> #REF!
A11: Connecticut | B11: {=VLOOKUP($A11,CT_DEMO,{2,5,6,7,8,9,10,11,12,4},FALSE)} -> 3605944 | C11: 2395128 | D11: 388675 | E11: 16051 | F11: 172455 | G11: 1598 | H11: 299133 | I11: 332904 | J11: 76366 | K11: 13.8 | L11: =#REF! -> #REF! | M11: {=VLOOKUP($A11,AFCARSCSC!$A$4:$D$56,{3,4},FALSE)} -> 438 | N11: 2363 | O11: NULL | P11: =#REF! -> #REF! | Q11: =#REF! -> #REF! | R11: =#REF! -> #REF! | S11: =(P11/B11)*1000 -> #REF!
A12: District of Columbia | B12: {=VLOOKUP($A12,DC_DEMO,{2,5,6,7,8,9,10,11,12,4},FALSE)} -> 689545 | C12: 273194 | D12: 285810 | E12: 3193 | F12: 33545 | G12: 432 | H12: 37294 | I12: 56077 | J12: 82533 | K12: 24.5 | L12: ='District of Columbia'!L3 -> 346 | M12: {=VLOOKUP($A12,AFCARSCSC!$A$4:$D$56,{3,4},FALSE)} -> 0 | N12: 386 | O12: =#REF! -> #REF! | P12: ='Population & Church Numbers'!D322 -> 480 | Q12: =P12*0.1 -> 48 | R12: =#REF! -> #REF! | S12: =(P12/B12)*1000 -> 0.6961112
A13: Delaware | B13: {=VLOOKUP($A13,DE_DEMO,{2,5,6,7,8,9,10,11,12,4},FALSE)} -> 989948 | C13: 597763 | D13: 218899 | E13: 5148 | F13: 42699 | G13: 412 | H13: 48509 | I13: 76518 | J13: 65467 | K13: 17.6 | L13: =#REF! -> #REF! | M13: =#REF! -> #REF! | N13: =#REF! -> #REF! | O13: NULL | P13: =#REF! -> #REF! | Q13: =#REF! -> #REF! | R13: =#REF! -> #REF! | S13: =(P13/B13)*1000 -> #REF!
A14: Florida | B14: {=VLOOKUP($A14,FL_DEMO,{2,5,6,7,8,9,10,11,12,4},FALSE)} -> 21538187 | C14: 12422961 | D14: 3246381 | E14: 94795 | F14: 643682 | G14: 14014 | H14: 1564282 | I14: 3552072 | J14: 55433 | K14: 20 | L14: =Florida!L71 -> NULL | M14: =VLOOKUP($A14,AFCARSCSC!$A$4:$D$56,3,FALSE) -> 5576 | N14: =VLOOKUP($A14,AFCARSCSC!$A$4:$D$56,4,FALSE) -> 8712 | O14: NULL | P14: =#REF! -> #REF! | Q14: =#REF! -> #REF! | R14: =#REF! -> #REF! | S14: =(P14/B14)*1000 -> #REF!
A15: Georgia | B15: {=VLOOKUP($A15,GA_DEMO,{2,5,6,7,8,9,10,11,12,4},FALSE)} -> 10711908 | C15: 5555483 | D15: 3320513 | E15: 50618 | F15: 479028 | G15: 7299 | H15: 555059 | I15: 743908 | J15: 58634 | K15: 21 | L15: =#REF! -> #REF! | M15: =#REF! -> #REF! | N15: =VLOOKUP($A15,AFCARSCSC!$A$4:$D$56,4,FALSE) -> 4559 | O15: NULL | P15: =#REF! -> #REF! | Q15: =#REF! -> #REF! | R15: =#REF! -> #REF! | S15: =(P15/B15)*1000 -> #REF!
A16: Hawaii | B16: ='County PopulationPovertyRacial '!B564 -> 1455271 | C16: ='County PopulationPovertyRacial '!E564 -> 333261 | D16: ='County PopulationPovertyRacial '!F564 -> 23417 | E16: ='County PopulationPovertyRacial '!G564 -> 4370 | F16: ='County PopulationPovertyRacial '!H564 -> 541902 | G16: ='County PopulationPovertyRacial '!I564 -> 157445 | H16: ='County PopulationPovertyRacial '!J564 -> 26747 | I16: ='County PopulationPovertyRacial '!K564 -> 368129 | J16: ='County PopulationPovertyRacial '!$L$564 -> 80527 | K16: ='County PopulationPovertyRacial '!D564 -> 11.8 | L16: {=VLOOKUP($A16,AFCARSCSC!$A$4:$D$56,{2,3,4},FALSE)} -> 1340 | M16: 228 | N16: 781 | O16: NULL | P16: =#REF! -> #REF! | Q16: =#REF! -> #REF! | R16: =#REF! -> #REF! | S16: =(P16/B16)*1000 -> #REF!
A17: Idaho | B17: ='County PopulationPovertyRacial '!$B$570 -> 1839106 | C17: ='County PopulationPovertyRacial '!$E$570 -> 1510360 | D17: ='County PopulationPovertyRacial '!$F$570 -> 15726 | E17: ='County PopulationPovertyRacial '!$G$570 -> 25621 | F17: ='County PopulationPovertyRacial '!$H$570 -> 26836 | G17: ='County PopulationPovertyRacial '!$I$570 -> 3726 | H17: ='County PopulationPovertyRacial '!$J$570 -> 103632 | I17: ='County PopulationPovertyRacial '!$K$570 -> 153205 | J17: ='County PopulationPovertyRacial '!$L$570 -> 55524 | K17: ='County PopulationPovertyRacial '!D570 -> 14.2 | L17: {=VLOOKUP($A17,AFCARSCSC!$A$4:$D$56,{2,3,4},FALSE)} -> 1548 | M17: 170 | N17: 1187 | O17: NULL | P17: =#REF! -> #REF! | Q17: =#REF! -> #REF! | R17: =#REF! -> #REF! | S17: =(P17/B17)*1000 -> #REF!
A18: Illinois | B18: {=VLOOKUP($A18,IL_DEMO,{2,5,6,7,8,9,10,11,12,4},FALSE)} -> 12812508 | C18: 7868227 | D18: 1808271 | E18: 96498 | F18: 754878 | G18: 4501 | H18: 1135149 | I18: 1144984 | J18: 65063 | K18: 16.2 | L18: =#REF! -> #REF! | M18: =VLOOKUP($A18,AFCARSCSC!$A$4:$D$56,3,FALSE) -> 2660 | N18: =#REF! -> #REF! | O18: NULL | P18: =#REF! -> #REF! | Q18: =#REF! -> #REF! | R18: =#REF! -> #REF! | S18: =(P18/B18)*1000 -> #REF!
A19: Indiana | B19: {=VLOOKUP($A19,IN_DEMO,{2,5,6,7,8,9,10,11,12,4},FALSE)} -> 6785528 | C19: 5241795 | D19: 648513 | E19: 26086 | F19: 167959 | G19: 3137 | H19: 261312 | I19: 436726 | J19: 55725 | K19: 17.5 | L19: =#REF! -> #REF! | M19: {=VLOOKUP($A19,AFCARSCSC!$A$4:$D$56,{3,4},FALSE)} -> 1389 | N19: 4531 | O19: =#REF! -> #REF! | P19: =#REF! -> #REF! | Q19: =#REF! -> #REF! | R19: =#REF! -> #REF! | S19: =(P19/B19)*1000 -> #REF!
A20: Iowa | B20: ='County PopulationPovertyRacial '!$B$811 -> 3190369 | C20: ='County PopulationPovertyRacial '!$E$811 -> 2694521 | D20: ='County PopulationPovertyRacial '!$F$811 -> 131972 | E20: ='County PopulationPovertyRacial '!$G$811 -> 14486 | F20: ='County PopulationPovertyRacial '!$H$811 -> 75629 | G20: ='County PopulationPovertyRacial '!$I$811 -> 5758 | H20: ='County PopulationPovertyRacial '!$J$811 -> 88720 | I20: ='County PopulationPovertyRacial '!$K$811 -> 179283 | J20: ='County PopulationPovertyRacial '!$L$811 -> 60071 | K20: ='County PopulationPovertyRacial '!$D$811 -> 13.5 | L20: =#REF! -> #REF! | M20: {=VLOOKUP($A20,AFCARSCSC!$A$4:$D$56,{3,4},FALSE)} -> 765 | N20: 2244 | O20: NULL | P20: =#REF! -> #REF! | Q20: =#REF! -> #REF! | R20: =#REF! -> #REF! | S20: =(P20/B20)*1000 -> #REF!
A21: Kansas | B21: {=VLOOKUP($A21,KS_DEMO,{2,5,6,7,8,9,10,11,12,4},FALSE)} -> 2937880 | C21: 2222462 | D21: 168809 | E21: 30995 | F21: 86273 | G21: 3412 | H21: 145422 | I21: 280507 | J21: 58150 | K21: 14.8 | L21: =#REF! -> #REF! | M21: =#REF! -> #REF! | N21: =#REF! -> #REF! | O21: NULL | P21: =#REF! -> #REF! | Q21: =#REF! -> #REF! | R21: =#REF! -> #REF! | S21: =(P21/B21)*1000 -> #REF!
A22: Kentucky | B22: {=VLOOKUP($A22,KY_DEMO,{2,5,6,7,8,9,10,11,12,4},FALSE)} -> 4505836 | C22: 3711254 | D22: 362417 | E22: 12801 | F22: 74426 | G22: 3681 | H22: 96417 | I22: 244840 | J22: 50189 | K22: 22.3 | L22: =#REF! -> #REF! | M22: =#REF! -> #REF! | N22: =VLOOKUP($A22,AFCARSCSC!$A$4:$D$56,4,FALSE) -> 5185 | O22: NULL | P22: =#REF! -> #REF! | Q22: =#REF! -> #REF! | R22: =#REF! -> #REF! | S22: =(P22/B22)*1000 -> #REF!
A23: Louisiana | B23: {=VLOOKUP($A23,LA_DEMO,{2,5,6,7,8,9,10,11,12,4},FALSE)} -> 4657757 | C23: 2657652 | D23: 1464023 | E23: 31657 | F23: 86438 | G23: 1911 | H23: 142699 | I23: 273377 | J23: 48021 | K23: 26.5 | L23: {=VLOOKUP($A23,AFCARSCSC!$A$4:$D$56,{2,3,4},FALSE)} -> 3682 | M23: 501 | N23: 1659 | O23: NULL | P23: =#REF! -> #REF! | Q23: =#REF! -> #REF! | R23: =#REF! -> #REF! | S23: =(P23/B23)*1000 -> #REF!
A24: Maine | B24: {=VLOOKUP($A24,ME_DEMO,{2,5,6,7,8,9,10,11,12,4},FALSE)} -> 1338404 | C24: 1237041 | D24: 25752 | E24: 7885 | F24: 16798 | G24: 443 | H24: 9730 | I24: 64710 | J24: 55579 | K24: 14.8 | L24: =#REF! -> #REF! | M24: {=VLOOKUP($A24,AFCARSCSC!$A$4:$D$56,{3,4},FALSE)} -> 107 | N24: 1767 | O24: NULL | P24: =#REF! -> #REF! | Q24: =#REF! -> #REF! | R24: =#REF! -> #REF! | S24: =(P24/B24)*1000 -> #REF!
A25: Maryland | B25: {=VLOOKUP($A25,MD_DEMO,{2,5,6,7,8,9,10,11,12,4},FALSE)} -> 6177224 | C25: 3007874 | D25: 1820472 | E25: 31845 | F25: 420944 | G25: 3247 | H25: 410941 | I25: 481901 | J25: 83076 | K25: 12.1 | L25: =#REF! -> #REF! | M25: =#REF! -> #REF! | N25: =#REF! -> #REF! | O25: =#REF! -> #REF! | P25: =#REF! -> #REF! | Q25: =#REF! -> #REF! | R25: =#REF! -> #REF! | S25: =(P25/B25)*1000 -> #REF!
A26: Massachusetts | B26: {=VLOOKUP($A26,MA_DEMO,{2,5,6,7,8,9,10,11,12,4},FALSE)} -> 7029917 | C26: 4896037 | D26: 494029 | E26: 24018 | F26: 507934 | G26: 2301 | H26: 496731 | I26: 608867 | J26: 79817 | K26: 12.4 | L26: {=VLOOKUP($A26,AFCARSCSC!$A$4:$D$56,{2,3,4},FALSE)} -> 8824 | M26: 1316 | N26: 5159 | O26: NULL | P26: =#REF! -> #REF! | Q26: =#REF! -> #REF! | R26: =#REF! -> #REF! | S26: =(P26/B26)*1000 -> #REF!
A27: Michigan | B27: {=VLOOKUP($A27,MI_DEMO,{2,5,6,7,8,9,10,11,12,4},FALSE)} -> 10077331 | C27: 7444974 | D27: 1376579 | E27: 61261 | F27: 334300 | G27: 3051 | H27: 221851 | I27: 635315 | J27: 56640 | K27: 19.3 | L27: =#REF! -> #REF! | M27: =#REF! -> #REF! | N27: =VLOOKUP($A27,AFCARSCSC!$A$4:$D$56,4,FALSE) -> 4169 | O27: NULL | P27: =#REF! -> #REF! | Q27: =#REF! -> #REF! | R27: =#REF! -> #REF! | S27: =(P27/B27)*1000 -> #REF!
A28: Minnesota | B28: {=VLOOKUP($A28,MN_DEMO,{2,5,6,7,8,9,10,11,12,4},FALSE)} -> 5706494 | C28: 4423146 | D28: 398434 | E28: 68641 | F28: 299190 | G28: 2918 | H28: 168444 | I28: 345721 | J28: 70295 | K28: 11.5 | L28: =#REF! -> #REF! | M28: {=VLOOKUP($A28,AFCARSCSC!$A$4:$D$56,{3,4},FALSE)} -> 1423 | N28: 3766 | O28: NULL | P28: =#REF! -> #REF! | Q28: =#REF! -> #REF! | R28: =#REF! -> #REF! | S28: =(P28/B28)*1000 -> #REF!
A29: Mississippi | B29: {=VLOOKUP($A29,MS_DEMO,{2,5,6,7,8,9,10,11,12,4},FALSE)} -> 2961279 | C29: 1658893 | D29: 1084481 | E29: 16450 | F29: 32709 | G29: 1154 | H29: 56860 | I29: 110732 | J29: 44740 | K29: 28.2 | L29: {=VLOOKUP($A29,AFCARSCSC!$A$4:$D$56,{2,3,4},FALSE)} -> 3825 | M29: 530 | N29: 1691 | O29: NULL | P29: =#REF! -> #REF! | Q29: =#REF! -> #REF! | R29: =#REF! -> #REF! | S29: =(P29/B29)*1000 -> #REF!
A30: Missouri | B30: {=VLOOKUP($A30,MO_DEMO,{2,5,6,7,8,9,10,11,12,4},FALSE)} -> 6154913 | C30: 4740335 | D30: 699840 | E30: 30518 | F30: 133377 | G30: 9730 | H30: 127942 | I30: 413171 | J30: 54412 | K30: 18.3 | L30: =#REF! -> #REF! | M30: =#REF! -> #REF! | N30: =VLOOKUP($A30,AFCARSCSC!$A$4:$D$56,4,FALSE) -> 4567 | O30: =#REF! -> #REF! | P30: =#REF! -> #REF! | Q30: =#REF! -> #REF! | R30: =#REF! -> #REF! | S30: =(P30/B30)*1000 -> #REF!
A31: Montana | B31: {=VLOOKUP($A31,MT_DEMO,{2,5,6,7,8,9,10,11,12,4},FALSE)} -> 1084225 | C31: 916524 | D31: 5484 | E31: 67612 | F31: 8300 | G31: 941 | H31: 14089 | I31: 71275 | J31: 55248 | K31: 16.4 | L31: =#REF! -> #REF! | M31: {=VLOOKUP($A31,AFCARSCSC!$A$4:$D$56,{3,4},FALSE)} -> 345 | N31: 1200 | O31: NULL | P31: =#REF! -> #REF! | Q31: =#REF! -> #REF! | R31: =#REF! -> #REF! | S31: =(P31/B31)*1000 -> #REF!
A32: Nebraska | B32: {=VLOOKUP($A32,NE_DEMO,{2,5,6,7,8,9,10,11,12,4},FALSE)} -> 1961504 | C32: 1538052 | D32: 96535 | E32: 23102 | F32: 52951 | G32: 1534 | H32: 105167 | I32: 144163 | J32: 59724 | K32: 12.9 | L32: =#REF! -> #REF! | M32: {=VLOOKUP($A32,AFCARSCSC!$A$4:$D$56,{3,4},FALSE)} -> 433 | N32: 1502 | O32: NULL | P32: =#REF! -> #REF! | Q32: =#REF! -> #REF! | R32: =#REF! -> #REF! | S32: =(P32/B32)*1000 -> #REF!
A33: Nevada | B33: {=VLOOKUP($A33,NV_DEMO,{2,5,6,7,8,9,10,11,12,4},FALSE)} -> 3104614 | C33: 1588463 | D33: 304739 | E33: 43932 | F33: 272703 | G33: 25011 | H33: 435757 | I33: 434009 | J33: 58740 | K33: 18.4 | L33: =#REF! -> #REF! | M33: {=VLOOKUP($A33,AFCARSCSC!$A$4:$D$56,{3,4},FALSE)} -> 718 | N33: 1099 | O33: NULL | P33: =#REF! -> #REF! | Q33: =#REF! -> #REF! | R33: =#REF! -> #REF! | S33: =(P33/B33)*1000 -> #REF!
A34: New Hampshire | B34: {=VLOOKUP($A34,NH_DEMO,{2,5,6,7,8,9,10,11,12,4},FALSE)} -> 1377529 | C34: 1216203 | D34: 20127 | E34: 3031 | F34: 35871 | G34: 453 | H34: 24102 | I34: 77742 | J34: 75322 | K34: 10.1 | L34: {=VLOOKUP($A34,AFCARSCSC!$A$4:$D$56,{2,3,4},FALSE)} -> 1181 | M34: 60 | N34: 599 | O34: NULL | P34: =#REF! -> #REF! | Q34: =#REF! -> #REF! | R34: =#REF! -> #REF! | S34: =(P34/B34)*1000 -> #REF!
A35: New Jersey | B35: {=VLOOKUP($A35,NJ_DEMO,{2,5,6,7,8,9,10,11,12,4},FALSE)} -> 9288994 | C35: 5112280 | D35: 1219770 | E35: 51186 | F35: 950090 | G35: 3533 | H35: 1048641 | I35: 903494 | J35: 81777 | K35: 13.5 | L35: =#REF! -> #REF! | M35: {=VLOOKUP($A35,AFCARSCSC!$A$4:$D$56,{3,4},FALSE)} -> 444 | N35: 2449 | O35: NULL | P35: =#REF! -> #REF! | Q35: =#REF! -> #REF! | R35: =#REF! -> #REF! | S35: =(P35/B35)*1000 -> #REF!
A36: New Mexico | B36: {=VLOOKUP($A36,NM_DEMO,{2,5,6,7,8,9,10,11,12,4},FALSE)} -> 2117522 | C36: 1078937 | D36: 45904 | E36: 212241 | F36: 37469 | G36: 2093 | H36: 318632 | I36: 422246 | J36: 47405 | K36: 25.3 | L36: ='NM Data'!B77 -> 1942 | M36: =#REF! -> #REF! | N36: =VLOOKUP($A36,AFCARSCSC!$A$4:$D$56,4,FALSE) -> 1007 | O36: NULL | P36: =#REF! -> #REF! | Q36: =#REF! -> #REF! | R36: =#REF! -> #REF! | S36: =(P36/B36)*1000 -> #REF!
A37: New York | B37: ='County PopulationPovertyRacial '!B1867 -> 20201249 | C37: ='County PopulationPovertyRacial '!E1867 -> 11143349 | D37: ='County PopulationPovertyRacial '!F1867 -> 2986172 | E37: ='County PopulationPovertyRacial '!G1867 -> 149690 | F37: ='County PopulationPovertyRacial '!H1867 -> 1933127 | G37: ='County PopulationPovertyRacial '!I1867 -> 10815 | H37: ='County PopulationPovertyRacial '!J1867 -> 2210633 | I37: ='County PopulationPovertyRacial '!K1867 -> 1767463 | J37: ='County PopulationPovertyRacial '!$L$1867 -> 67648 | K37: ='County PopulationPovertyRacial '!D1867 -> 18.8 | L37: =#REF! -> #REF! | M37: =#REF! -> #REF! | N37: =#REF! -> #REF! | O37: NULL | P37: =#REF! -> #REF! | Q37: =#REF! -> #REF! | R37: =#REF! -> #REF! | S37: =(P37/B37)*1000 -> #REF!
A38: North Carolina | B38: {=VLOOKUP($A38,NC_DEMO,{2,5,6,7,8,9,10,11,12,4},FALSE)} -> 10439388 | C38: 6488459 | D38: 2140217 | E38: 130032 | F38: 343051 | G38: 8518 | H38: 617390 | I38: 711721 | J38: 53922 | K38: 20.2 | L38: =#REF! -> #REF! | M38: {=VLOOKUP($A38,AFCARSCSC!$A$4:$D$56,{3,4},FALSE)} -> 1154 | N38: 5616 | O38: NULL | P38: =#REF! -> #REF! | Q38: =#REF! -> #REF! | R38: =#REF! -> #REF! | S38: =(P38/B38)*1000 -> #REF!
A39: North Dakota | B39: {=VLOOKUP($A39,ND_DEMO,{2,5,6,7,8,9,10,11,12,4},FALSE)} -> 779094 | C39: 645938 | D39: 26783 | E39: 38914 | F39: 13213 | G39: 924 | H39: 11382 | I39: 41940 | J39: 65250 | K39: 11 | L39: =#REF! -> #REF! | M39: {=VLOOKUP($A39,AFCARSCSC!$A$4:$D$56,{3,4},FALSE)} -> 343 | N39: 974 | O39: NULL | P39: =#REF! -> #REF! | Q39: =#REF! -> #REF! | R39: =#REF! -> #REF! | S39: =(P39/B39)*1000 -> #REF!
A40: Ohio | B40: {=VLOOKUP($A40,OH_DEMO,{2,5,6,7,8,9,10,11,12,4},FALSE)} -> 11799448 | C40: 9080688 | D40: 1478781 | E40: 30720 | F40: 298509 | G40: 5034 | H40: 224344 | I40: 681372 | J40: 56155 | K40: 19.2 | L40: =#REF! -> #REF! | M40: =#REF! -> #REF! | N40: {=VLOOKUP($A40,AFCARSCSC!$A$4:$D$56,4,FALSE)} -> 7349 | O40: NULL | P40: =#REF! -> #REF! | Q40: =#REF! -> #REF! | R40: =#REF! -> #REF! | S40: =(P40/B40)*1000 -> #REF!
...

Sheet Top 50%
D2: Top 130 Counties- 50% of Children in Care
D3: County Demographics | N3: Foster Care Data | S3: Church Data
E4: Population by Race
B5: County | C5: State | D5: County Population | E5: White | F5: Black or African American | G5: American Indian and Alaska Native | H5: Asian | I5: Native Hawaiian and Other Pacific Islander | J5: Other race | K5: Two or more races | L5: Median Household Income | M5: Poverty Rate | N5: Number of Children in Out-of-Home Placement | O5: Number of Children in Kinship Care | P5: Number of Children Waiting for Adoption | Q5: Number of Licensed Foster Homes | R5: Number of Family Preservation Cases | S5: Number of Churches | T5: Number of Actively Engaged Churches Needed | U5: Churches per 1,000 People | V5: Children in Care per Church | W5: Churches per Children in Care
A6: 1 | B6: Los Angeles | C6: CA | D6: =California!B$21 -> 10014009 | E6: =California!C$21 -> 15018 | F6: =California!D$21 -> NULL | G6: =California!E$21 -> 6150 | H6: =California!F$21 -> 6029 | I6: =California!G$21 -> NULL | J6: =California!H$21 -> NULL | K6: =California!I$21 -> 3563 | ... M6: =California!K$21 -> 0.48168193 | N6: {=VLOOKUP($B6,'CarePortal - Audrey'!$A$2:$T$166,{8,17,18,20},FALSE)} -> #REF! | O6: #REF! | P6: #REF! | Q6: #REF! | R6: =#REF! -> #REF! | S6: =#REF! -> #REF! | T6: =#REF! -> #REF! | U6: =#REF! -> #REF! | V6: =#REF! -> #REF! | W6: =#REF! -> #REF!
A7: 2 | B7: Cook | C7: IL | D7: =Illinois!B$18 -> 5275541 | E7: =Illinois!C$18 -> 2458 | F7: =Illinois!D$18 -> NULL | G7: =Illinois!E$18 -> 1044 | H7: =Illinois!F$18 -> 1191 | I7: =Illinois!G$18 -> NULL | J7: =Illinois!H$18 -> 1282 | K7: =Illinois!I$18 -> 169 | ... M7: =Illinois!K$18 -> NULL | N7: {=VLOOKUP($B7,'CarePortal - Audrey'!$A$2:$T$166,{8,17,18,20},FALSE)} -> #REF! | O7: #REF! | P7: #REF! | Q7: #REF! | R7: =#REF! -> #REF! | S7: =#REF! -> #REF! | T7: =#REF! -> #REF! | U7: =#REF! -> #REF! | V7: =#REF! -> #REF! | W7: =#REF! -> #REF!
A8: 3 | B8: Harris | C8: TX | D8: =#REF! -> #REF! | E8: =#REF! -> #REF! | F8: =#REF! -> #REF! | G8: =#REF! -> #REF! | H8: =#REF! -> #REF! | I8: =#REF! -> #REF! | J8: =#REF! -> #REF! | K8: =#REF! -> #REF! | ... M8: =#REF! -> #REF! | N8: {=VLOOKUP($B8,'CarePortal - Audrey'!$A$2:$T$166,{8,17,18,20},FALSE)} -> #REF! | O8: #REF! | P8: #REF! | Q8: #REF! | R8: =#REF! -> #REF! | S8: =#REF! -> #REF! | T8: =#REF! -> #REF! | U8: =#REF! -> #REF! | V8: =#REF! -> #REF! | W8: =#REF! -> #REF!
A9: 4 | B9: Maricopa | C9: AZ | D9: =Arizona!B$10 -> 4420568 | E9: =Arizona!C$10 -> 5184 | F9: =Arizona!D$10 -> NULL | G9: =Arizona!E$10 -> NULL | H9: =Arizona!F$10 -> NULL | I9: =Arizona!G$10 -> NULL | J9: =Arizona!H$10 -> NULL | K9: =Arizona!I$10 -> NULL | ... M9: =Arizona!K$10 -> NULL | N9: {=VLOOKUP($B9,'CarePortal - Audrey'!$A$2:$T$166,{8,17,18,20},FALSE)} -> #REF! | O9: #REF! | P9: #REF! | Q9: #REF! | R9: =#REF! -> #REF! | S9: =#REF! -> #REF! | T9: =#REF! -> #REF! | U9: =#REF! -> #REF! | V9: =#REF! -> #REF! | W9: =#REF! -> #REF!
A10: 5 | B10: San Diego | C10: CA | D10: =California!B$39 -> 3298634 | E10: =California!C$39 -> 1655 | F10: =California!D$39 -> NULL | G10: =California!E$39 -> 636 | H10: =California!F$39 -> 587 | I10: =California!G$39 -> NULL | J10: =California!H$39 -> NULL | K10: =California!I$39 -> 192 | ... M10: =California!K$39 -> 0.45605469 | N10: {=VLOOKUP($B10,'CarePortal - Audrey'!$A$2:$T$166,{8,17,18,20},FALSE)} -> #REF! | O10: #REF! | P10: #REF! | Q10: #REF! | R10: =#REF! -> #REF! | S10: =#REF! -> #REF! | T10: =#REF! -> #REF! | U10: =#REF! -> #REF! | V10: =#REF! -> #REF! | W10: =#REF! -> #REF!
A11: 6 | B11: Orange | C11: CA | D11: =California!B$32 -> 3186989 | E11: =California!C$32 -> 2205 | F11: =California!D$32 -> NULL | G11: =California!E$32 -> 543 | H11: =California!F$32 -> 1107 | I11: =California!G$32 -> NULL | J11: =California!H$32 -> NULL | K11: =California!I$32 -> 344 | ... M11: =California!K$32 -> 0.52457695 | N11: {=VLOOKUP($B11,'CarePortal - Audrey'!$A$2:$T$166,{8,17,18,20},FALSE)} -> #REF! | O11: #REF! | P11: #REF! | Q11: #REF! | R11: =#REF! -> #REF! | S11: =#REF! -> #REF! | T11: =#REF! -> #REF! | U11: =#REF! -> #REF! | V11: =#REF! -> #REF! | W11: =#REF! -> #REF!
A12: 7 | B12: Miami-Dade | C12: FL | D12: =Florida!B$45 -> 2701767 | E12: =Florida!C$45 -> 1338 | F12: =Florida!D$45 -> NULL | G12: =Florida!E$45 -> 709 | H12: =Florida!F$45 -> 348 | I12: =Florida!G$45 -> NULL | J12: =Florida!H$45 -> NULL | K12: =Florida!I$45 -> NULL | ... M12: =Florida!K$45 -> 0.65799257 | N12: {=VLOOKUP($B12,'CarePortal - Audrey'!$A$2:$T$166,{8,17,18,20},FALSE)} -> #REF! | O12: #REF! | P12: #REF! | Q12: #REF! | R12: =#REF! -> #REF! | S12: =#REF! -> #REF! | T12: =#REF! -> #REF! | U12: =#REF! -> #REF! | V12: =#REF! -> #REF! | W12: =#REF! -> #REF!
A13: 8 | B13: Dallas | C13: TX | D13: =Texas!B$254 -> 17867 | E13: =Texas!C$254 -> 50 | F13: =Texas!D$254 -> NULL | G13: =Texas!E$254 -> 29 | H13: =Texas!F$254 -> 16 | I13: =Texas!G$254 -> NULL | J13: =Texas!H$254 -> 21 | K13: =Texas!I$254 -> 1 | ... M13: =Texas!K$254 -> NULL | N13: {=VLOOKUP($B13,'CarePortal - Audrey'!$A$2:$T$166,{8,17,18,20},FALSE)} -> #REF! | O13: #REF! | P13: #REF! | Q13: #REF! | R13: =#REF! -> #REF! | S13: =#REF! -> #REF! | T13: =#REF! -> #REF! | U13: =#REF! -> #REF! | V13: =#REF! -> #REF! | W13: =#REF! -> #REF!
A14: 9 | B14: Kings | C14: NY | D14: ='New York'!B$26 -> 2736074 | E14: ='New York'!C$26 -> NULL | F14: ='New York'!D$26 -> NULL | G14: ='New York'!E$26 -> NULL | H14: ='New York'!F$26 -> NULL | I14: ='New York'!G$26 -> NULL | J14: ='New York'!H$26 -> NULL | K14: ='New York'!I$26 -> NULL | ... M14: ='New York'!K$26 -> NULL | N14: {=VLOOKUP($B14,'CarePortal - Audrey'!$A$2:$T$166,{8,17,18,20},FALSE)} -> #REF! | O14: #REF! | P14: #REF! | Q14: #REF! | R14: =#REF! -> #REF! | S14: =#REF! -> #REF! | T14: =#REF! -> #REF! | U14: =#REF! -> #REF! | V14: =#REF! -> #REF! | W14: =#REF! -> #REF!
A15: 10 | B15: Riverside | C15: CA | D15: =California!B$35 -> 2418185 | E15: =California!C$35 -> 3119 | F15: =California!D$35 -> NULL | G15: =California!E$35 -> 1320 | H15: =California!F$35 -> 1177 | I15: =California!G$35 -> NULL | J15: =California!H$35 -> NULL | K15: =California!I$35 -> 357 | ... M15: =California!K$35 -> 0.52603471 | N15: {=VLOOKUP($B15,'CarePortal - Audrey'!$A$2:$T$166,{8,17,18,20},FALSE)} -> #REF! | O15: #REF! | P15: #REF! | Q15: #REF! | R15: =#REF! -> #REF! | S15: =#REF! -> #REF! | T15: =#REF! -> #REF! | U15: =#REF! -> #REF! | V15: =#REF! -> #REF! | W15: =#REF! -> #REF!
A16: 11 | B16: Queens | C16: NY | D16: ='New York'!B$43 -> 2405464 | E16: ='New York'!C$43 -> NULL | F16: ='New York'!D$43 -> NULL | G16: ='New York'!E$43 -> NULL | H16: ='New York'!F$43 -> NULL | I16: ='New York'!G$43 -> NULL | J16: ='New York'!H$43 -> NULL | K16: ='New York'!I$43 -> NULL | ... M16: ='New York'!K$43 -> NULL | N16: {=VLOOKUP($B16,'CarePortal - Audrey'!$A$2:$T$166,{8,17,18,20},FALSE)} -> #REF! | O16: #REF! | P16: #REF! | Q16: #REF! | R16: =#REF! -> #REF! | S16: =#REF! -> #REF! | T16: =#REF! -> #REF! | U16: =#REF! -> #REF! | V16: =#REF! -> #REF! | W16: =#REF! -> #REF!
A17: 12 | B17: King | C17: WA | D17: =Washington!B$19 -> 2269675 | E17: =Washington!C$19 -> NULL | F17: =Washington!D$19 -> NULL | G17: =Washington!E$19 -> NULL | H17: =Washington!F$19 -> NULL | I17: =Washington!G$19 -> NULL | J17: =Washington!H$19 -> NULL | K17: =Washington!I$19 -> NULL | ... M17: =Washington!K$19 -> NULL | N17: {=VLOOKUP($B17,'CarePortal - Audrey'!$A$2:$T$166,{8,17,18,20},FALSE)} -> #REF! | O17: #REF! | P17: #REF! | Q17: #REF! | R17: =#REF! -> #REF! | S17: =#REF! -> #REF! | T17: =#REF! -> #REF! | U17: =#REF! -> #REF! | V17: =#REF! -> #REF! | W17: =#REF! -> #REF!
A18: 13 | B18: Clark | C18: NV | D18: =Nevada!B$5 -> 49488 | E18: =Nevada!C$5 -> NULL | F18: =Nevada!D$5 -> NULL | G18: =Nevada!E$5 -> NULL | H18: =Nevada!F$5 -> NULL | I18: =Nevada!G$5 -> NULL | J18: =Nevada!H$5 -> NULL | K18: =Nevada!I$5 -> NULL | ... M18: =Nevada!K$5 -> NULL | N18: {=VLOOKUP($B18,'CarePortal - Audrey'!$A$2:$T$166,{8,17,18,20},FALSE)} -> #REF! | O18: #REF! | P18: #REF! | Q18: #REF! | R18: =#REF! -> #REF! | S18: =#REF! -> #REF! | T18: =#REF! -> #REF! | U18: =#REF! -> #REF! | V18: =#REF! -> #REF! | W18: =#REF! -> #REF!
A19: 14 | B19: San Bernardino | C19: CA | D19: =California!B$38 -> 2181654 | E19: =California!C$38 -> 4996 | F19: =California!D$38 -> NULL | G19: =California!E$38 -> 2220 | H19: =California!F$38 -> 1544 | I19: =California!G$38 -> NULL | J19: =California!H$38 -> NULL | K19: =California!I$38 -> 643 | ... M19: =California!K$38 -> 0.45051635 | N19: {=VLOOKUP($B19,'CarePortal - Audrey'!$A$2:$T$166,{8,17,18,20},FALSE)} -> #REF! | O19: #REF! | P19: #REF! | Q19: #REF! | R19: =#REF! -> #REF! | S19: =#REF! -> #REF! | T19: =#REF! -> #REF! | U19: =#REF! -> #REF! | V19: =#REF! -> #REF! | W19: =#REF! -> #REF!
A20: 15 | B20: Tarrant | C20: TX | D20: =#REF! -> #REF! | E20: =#REF! -> #REF! | F20: =#REF! -> #REF! | G20: =#REF! -> #REF! | H20: =#REF! -> #REF! | I20: =#REF! -> #REF! | J20: =#REF! -> #REF! | K20: =#REF! -> #REF! | ... M20: =#REF! -> #REF! | N20: {=VLOOKUP($B20,'CarePortal - Audrey'!$A$2:$T$166,{8,17,18,20},FALSE)} -> #REF! | O20: #REF! | P20: #REF! | Q20: #REF! | R20: =#REF! -> #REF! | S20: =#REF! -> #REF! | T20: =#REF! -> #REF! | U20: =#REF! -> #REF! | V20: =#REF! -> #REF! | W20: =#REF! -> #REF!
A21: 16 | B21: Bexar | C21: TX | D21: =Texas!B$212 -> 24022 | E21: =Texas!C$212 -> 28 | F21: =Texas!D$212 -> NULL | G21: =Texas!E$212 -> 13 | H21: =Texas!F$212 -> 13 | I21: =Texas!G$212 -> NULL | J21: =Texas!H$212 -> 18 | K21: =Texas!I$212 -> 4 | ... M21: =Texas!K$212 -> NULL | N21: {=VLOOKUP($B21,'CarePortal - Audrey'!$A$2:$T$166,{8,17,18,20},FALSE)} -> #REF! | O21: #REF! | P21: #REF! | Q21: #REF! | R21: =#REF! -> #REF! | S21: =#REF! -> #REF! | T21: =#REF! -> #REF! | U21: =#REF! -> #REF! | V21: =#REF! -> #REF! | W21: =#REF! -> #REF!
A22: 17 | B22: Broward | C22: FL | D22: =Florida!B$8 -> 1944375 | E22: =Florida!C$8 -> 1067 | F22: =Florida!D$8 -> NULL | G22: =Florida!E$8 -> 456 | H22: =Florida!F$8 -> 365 | I22: =Florida!G$8 -> NULL | J22: =Florida!H$8 -> NULL | K22: =Florida!I$8 -> NULL | ... M22: =Florida!K$8 -> 0.6872093 | N22: {=VLOOKUP($B22,'CarePortal - Audrey'!$A$2:$T$166,{8,17,18,20},FALSE)} -> #REF! | O22: #REF! | P22: #REF! | Q22: #REF! | R22: =#REF! -> #REF! | S22: =#REF! -> #REF! | T22: =#REF! -> #REF! | U22: =#REF! -> #REF! | V22: =#REF! -> #REF! | W22: =#REF! -> #REF!
A23: 18 | B23: Santa Clara | C23: CA | D23: =California!B$45 -> 1936259 | E23: =California!C$45 -> 494 | F23: =California!D$45 -> NULL | G23: =California!E$45 -> 234 | H23: =California!F$45 -> 111 | I23: =California!G$45 -> NULL | J23: =California!H$45 -> NULL | K23: =California!I$45 -> 85 | ... M23: =California!K$45 -> 0.22772277 | N23: {=VLOOKUP($B23,'CarePortal - Audrey'!$A$2:$T$166,{8,17,18,20},FALSE)} -> #REF! | O23: #REF! | P23: #REF! | Q23: #REF! | R23: =#REF! -> #REF! | S23: =#REF! -> #REF! | T23: =#REF! -> #REF! | U23: =#REF! -> #REF! | V23: =#REF! -> #REF! | W23: =#REF! -> #REF!
A24: 19 | B24: Wayne | C24: MI | D24: =#REF! -> #REF! | E24: =#REF! -> #REF! | F24: =#REF! -> #REF! | G24: =#REF! -> #REF! | H24: =#REF! -> #REF! | I24: =#REF! -> #REF! | J24: =#REF! -> #REF! | K24: =#REF! -> #REF! | ... M24: =#REF! -> #REF! | N24: {=VLOOKUP($B24,'CarePortal - Audrey'!$A$2:$T$166,{8,17,18,20},FALSE)} -> #REF! | O24: #REF! | P24: #REF! | Q24: #REF! | R24: =#REF! -> #REF! | S24: =#REF! -> #REF! | T24: =#REF! -> #REF! | U24: =#REF! -> #REF! | V24: =#REF! -> #REF! | W24: =#REF! -> #REF!
A25: 20 | B25: Alameda | C25: CA | D25: =California!B$3 -> 1682353 | E25: =California!C$3 -> 916 | F25: =California!D$3 -> NULL | G25: =California!E$3 -> 294 | H25: =California!F$3 -> 336 | I25: =California!G$3 -> NULL | J25: =California!H$3 -> NULL | K25: =California!I$3 -> 86 | ... M25: =California!K$3 -> 0.40648379 | N25: {=VLOOKUP($B25,'CarePortal - Audrey'!$A$2:$T$166,{8,17,18,20},FALSE)} -> #REF! | O25: #REF! | P25: #REF! | Q25: #REF! | R25: =#REF! -> #REF! | S25: =#REF! -> #REF! | T25: =#REF! -> #REF! | U25: =#REF! -> #REF! | V25: =#REF! -> #REF! | W25: =#REF! -> #REF!
A26: 21 | B26: New York | C26: NY | D26: ='New York'!B$33 -> 1694251 | E26: ='New York'!C$33 -> NULL | F26: ='New York'!D$33 -> NULL | G26: ='New York'!E$33 -> NULL | H26: ='New York'!F$33 -> NULL | I26: ='New York'!G$33 -> NULL | J26: ='New York'!H$33 -> NULL | K26: ='New York'!I$33 -> NULL | ... M26: ='New York'!K$33 -> NULL | N26: {=VLOOKUP($B26,'CarePortal - Audrey'!$A$2:$T$166,{8,17,18,20},FALSE)} -> #REF! | O26: #REF! | P26: #REF! | Q26: #REF! | R26: =#REF! -> #REF! | S26: =#REF! -> #REF! | T26: =#REF! -> #REF! | U26: =#REF! -> #REF! | V26: =#REF! -> #REF! | W26: =#REF! -> #REF!
A27: 22 | B27: Middlesex | C27: MA | D27: =#REF! -> #REF! | E27: =#REF! -> #REF! | F27: =#REF! -> #REF! | G27: =#REF! -> #REF! | H27: =#REF! -> #REF! | I27: =#REF! -> #REF! | J27: =#REF! -> #REF! | K27: =#REF! -> #REF! | ... M27: =#REF! -> #REF! | N27: {=VLOOKUP($B27,'CarePortal - Audrey'!$A$2:$T$166,{8,17,18,20},FALSE)} -> #REF! | O27: #REF! | P27: #REF! | Q27: #REF! | R27: =#REF! -> #REF! | S27: =#REF! -> #REF! | T27: =#REF! -> #REF! | U27: =#REF! -> #REF! | V27: =#REF! -> #REF! | W27: =#REF! -> #REF!
A28: 23 | B28: Philadelphia | C28: PA | D28: =Pennsylvania!B$53 -> 1603797 | E28: =Pennsylvania!C$53 -> 3753 | F28: =Pennsylvania!D$53 -> NULL | G28: =Pennsylvania!E$53 -> 1452 | H28: =Pennsylvania!F$53 -> 1850 | I28: =Pennsylvania!G$53 -> NULL | J28: =Pennsylvania!H$53 -> NULL | K28: =Pennsylvania!I$53 -> NULL | ... M28: =Pennsylvania!K$53 -> NULL | N28: {=VLOOKUP($B28,'CarePortal - Audrey'!$A$2:$T$166,{8,17,18,20},FALSE)} -> #REF! | O28: #REF! | P28: #REF! | Q28: #REF! | R28: =#REF! -> #REF! | S28: =#REF! -> #REF! | T28: =#REF! -> #REF! | U28: =#REF! -> #REF! | V28: =#REF! -> #REF! | W28: =#REF! -> #REF!
A29: 24 | B29: Sacramento | C29: CA | D29: =California!B$36 -> 1585055 | E29: =California!C$36 -> 1176 | F29: =California!D$36 -> NULL | G29: =California!E$36 -> 457 | H29: =California!F$36 -> 277 | I29: =California!G$36 -> NULL | J29: =California!H$36 -> NULL | K29: =California!I$36 -> 166 | ... M29: =California!K$36 -> 0.4616307 | N29: {=VLOOKUP($B29,'CarePortal - Audrey'!$A$2:$T$166,{8,17,18,20},FALSE)} -> #REF! | O29: #REF! | P29: #REF! | Q29: #REF! | R29: =#REF! -> #REF! | S29: =#REF! -> #REF! | T29: =#REF! -> #REF! | U29: =#REF! -> #REF! | V29: =#REF! -> #REF! | W29: =#REF! -> #REF!
A30: 25 | B30: Palm Beach | C30: FL | D30: =Florida!B$52 -> 1492191 | E30: =Florida!C$52 -> 854 | F30: =Florida!D$52 -> NULL | G30: =Florida!E$52 -> 347 | H30: =Florida!F$52 -> 289 | I30: =Florida!G$52 -> NULL | J30: =Florida!H$52 -> NULL | K30: =Florida!I$52 -> NULL | ... M30: =Florida!K$52 -> 0.7578534 | N30: {=VLOOKUP($B30,'CarePortal - Audrey'!$A$2:$T$166,{8,17,18,20},FALSE)} -> #REF! | O30: #REF! | P30: #REF! | Q30: #REF! | R30: =#REF! -> #REF! | S30: =#REF! -> #REF! | T30: =#REF! -> #REF! | U30: =#REF! -> #REF! | V30: =#REF! -> #REF! | W30: =#REF! -> #REF!
A31: 26 | B31: Suffolk | C31: NY | D31: ='New York'!B$54 -> 1525920 | E31: ='New York'!C$54 -> 518 | F31: ='New York'!D$54 -> 1.9534368 | G31: ='New York'!E$54 -> 241 | H31: ='New York'!F$54 -> 163 | I31: ='New York'!G$54 -> NULL | J31: ='New York'!H$54 -> 451 | K31: ='New York'!I$54 -> 170 | ... M31: ='New York'!K$54 -> 0.597 | N31: {=VLOOKUP($B31,'CarePortal - Audrey'!$A$2:$T$166,{8,17,18,20},FALSE)} -> #REF! | O31: #REF! | P31: #REF! | Q31: #REF! | R31: =#REF! -> #REF! | S31: =#REF! -> #REF! | T31: =#REF! -> #REF! | U31: =#REF! -> #REF! | V31: =#REF! -> #REF! | W31: =#REF! -> #REF!
A32: 27 | B32: Hillsborough | C32: FL | D32: =Florida!B$30 -> 1459762 | E32: =Florida!C$30 -> 1716 | F32: =Florida!D$30 -> NULL | G32: =Florida!E$30 -> 831 | H32: =Florida!F$30 -> 510 | I32: =Florida!G$30 -> NULL | J32: =Florida!H$30 -> NULL | K32: =Florida!I$30 -> NULL | ... M32: =Florida!K$30 -> 0.93942218 | N32: {=VLOOKUP($B32,'CarePortal - Audrey'!$A$2:$T$166,{8,17,18,20},FALSE)} -> #REF! | O32: #REF! | P32: #REF! | Q32: #REF! | R32: =#REF! -> #REF! | S32: =#REF! -> #REF! | T32: =#REF! -> #REF! | U32: =#REF! -> #REF! | V32: =#REF! -> #REF! | W32: =#REF! -> #REF!
A33: 28 | B33: Bronx | C33: NY | D33: ='New York'!B$5 -> 1472654 | E33: ='New York'!C$5 -> NULL | F33: ='New York'!D$5 -> NULL | G33: ='New York'!E$5 -> NULL | H33: ='New York'!F$5 -> NULL | I33: ='New York'!G$5 -> NULL | J33: ='New York'!H$5 -> NULL | K33: ='New York'!I$5 -> NULL | ... M33: ='New York'!K$5 -> NULL | N33: {=VLOOKUP($B33,'CarePortal - Audrey'!$A$2:$T$166,{8,17,18,20},FALSE)} -> #REF! | O33: #REF! | P33: #REF! | Q33: #REF! | R33: =#REF! -> #REF! | S33: =#REF! -> #REF! | T33: =#REF! -> #REF! | U33: =#REF! -> #REF! | V33: =#REF! -> #REF! | W33: =#REF! -> #REF!
A34: 29 | B34: Orange | C34: FL | D34: =Florida!B$50 -> 1429908 | E34: =Florida!C$50 -> 943 | F34: =Florida!D$50 -> NULL | G34: =Florida!E$50 -> 434 | H34: =Florida!F$50 -> 305 | I34: =Florida!G$50 -> NULL | J34: =Florida!H$50 -> NULL | K34: =Florida!I$50 -> NULL | ... M34: =Florida!K$50 -> 0.83755274 | N34: {=VLOOKUP($B34,'CarePortal - Audrey'!$A$2:$T$166,{8,17,18,20},FALSE)} -> #REF! | O34: #REF! | P34: #REF! | Q34: #REF! | R34: =#REF! -> #REF! | S34: =#REF! -> #REF! | T34: =#REF! -> #REF! | U34: =#REF! -> #REF! | V34: =#REF! -> #REF! | W34: =#REF! -> #REF!
A35: 30 | B35: Nassau | C35: NY | D35: ='New York'!B$32 -> 1395774 | E35: ='New York'!C$32 -> 159 | F35: ='New York'!D$32 -> 2.7647059 | G35: ='New York'!E$32 -> 87 | H35: ='New York'!F$32 -> 24 | I35: ='New York'!G$32 -> NULL | J35: ='New York'!H$32 -> 213 | K35: ='New York'!I$32 -> 37 | ... M35: ='New York'!K$32 -> 0.707 | N35: {=VLOOKUP($B35,'CarePortal - Audrey'!$A$2:$T$166,{8,17,18,20},FALSE)} -> #REF! | O35: #REF! | P35: #REF! | Q35: #REF! | R35: =#REF! -> #REF! | S35: =#REF! -> #REF! | T35: =#REF! -> #REF! | U35: =#REF! -> #REF! | V35: =#REF! -> #REF! | W35: =#REF! -> #REF!
A36: 31 | B36: Franklin | C36: OH | D36: =Ohio!B$88 -> 37102 | E36: =Ohio!C$88 -> 30 | F36: =Ohio!D$88 -> NULL | G36: =Ohio!E$88 -> 23 | H36: =Ohio!F$88 -> NULL | I36: =Ohio!G$88 -> NULL | J36: =Ohio!H$88 -> NULL | K36: =Ohio!I$88 -> NULL | ... M36: =Ohio!K$88 -> 0.69565217 | N36: {=VLOOKUP($B36,'CarePortal - Audrey'!$A$2:$T$166,{8,17,18,20},FALSE)} -> #REF! | O36: #REF! | P36: #REF! | Q36: #REF! | R36: =#REF! -> #REF! | S36: =#REF! -> #REF! | T36: =#REF! -> #REF! | U36: =#REF! -> #REF! | V36: =#REF! -> #REF! | W36: =#REF! -> #REF!
A37: 32 | B37: Hennepin | C37: MN | N37: {=VLOOKUP($B37,'CarePortal - Audrey'!$A$2:$T$166,{8,17,18,20},FALSE)} -> #REF! | O37: #REF! | P37: #REF! | Q37: #REF!
A38: 33 | B38: Oakland | C38: MI | N38: {=VLOOKUP($B38,'CarePortal - Audrey'!$A$2:$T$166,{8,17,18,20},FALSE)} -> #REF! | O38: #REF! | P38: #REF! | Q38: #REF!
A39: 34 | B39: Travis | C39: TX | N39: {=VLOOKUP($B39,'CarePortal - Audrey'!$A$2:$T$166,{8,17,18,20},FALSE)} -> #REF! | O39: #REF! | P39: #REF! | Q39: #REF!
